Workbook
Name UPDATE: 'Data Sheet'!$E$1

Sheet Dashboard
A2: TCS — 10-Year Performance Analysis Dashboard (FY2016–FY2025)
B6: Revenue FY25 | D6: Net Profit FY25 | F6: EBITDA Margin | H6: Return on Equity | J6: CFO FY25
B7: ₹2,55,324 Cr | D7: ₹48,553 Cr | F7: 27.86% | H7: 47.32% | J7: ₹48,908 Cr
B8: +6.0% YoY | D8: +5.8% YoY | F8: 10-Yr Avg: 29.4% | H8: 10-Yr Avg: 35.7% | J8: +10.3% YoY
B11: 📊 Revenue & Profitability (₹ Crore) | H11: 📈 Margin & Returns Analysis (%)
B12: Year | C12: Revenue | D12: Net Profit | E12: EBITDA | F12: CFO | H12: Year | I12: Net Margin | J12: EBITDA Margin | K12: ROE | L12: ROCE
B13: 2016 | C13: 108646 | D13: 24270 | E13: 33693 | F13: 19109 | H13: 2016 | I13: 0.2234 | J13: 0.3101 | K13: 0.299 | L13: 0.4037
B14: 2017 | C14: 117966 | D14: 26289 | E14: 36464 | F14: 25223 | H14: 2017 | I14: 0.2228 | J14: 0.3091 | K14: 0.2568 | L14: 0.3506
B15: 2018 | C15: 123104 | D15: 25826 | E15: 36104 | F15: 25067 | H15: 2018 | I15: 0.2098 | J15: 0.2933 | K15: 0.2612 | L15: 0.3573
B16: 2019 | C16: 146463 | D16: 31472 | E16: 43727 | F16: 28593 | H16: 2019 | I16: 0.2149 | J16: 0.2986 | K16: 0.3047 | L16: 0.4184
B17: 2020 | C17: 156949 | D17: 32340 | E17: 46594 | F17: 32369 | H17: 2020 | I17: 0.2061 | J17: 0.2969 | K17: 0.3311 | L17: 0.418
B18: 2021 | C18: 164177 | D18: 32430 | E18: 48330 | F18: 38802 | H18: 2021 | I18: 0.1975 | J18: 0.2944 | K18: 0.3546 | L18: 0.4508
B19: 2022 | C19: 191754 | D19: 38327 | E19: 56953 | F19: 39949 | H19: 2022 | I19: 0.1999 | J19: 0.297 | K19: 0.3863 | L19: 0.4997
B20: 2023 | C20: 225458 | D20: 42147 | E20: 62552 | F20: 41965 | H20: 2023 | I20: 0.1869 | J20: 0.2774 | K20: 0.4297 | L20: 0.5528
B21: 2024 | C21: 240893 | D21: 45908 | E21: 67569 | F21: 44338 | H21: 2024 | I21: 0.1906 | J21: 0.2805 | K21: 0.4712 | L21: 0.6021
B22: 2025 | C22: 255324 | D22: 48553 | E22: 71125 | F22: 48908 | H22: 2025 | I22: 0.1901 | J22: 0.2786 | K22: 0.4732 | L22: 0.5969
B23: 10-Yr CAGR | C23: 10.0% | D23: 8.0% | E23: 8.7% | F23: 11.0% | H23: 10-Yr Average | I23: 20.4% | J23: 29.4% | K23: 35.7% | L23: 46.5%
B25: 📊 Revenue vs Net Profit (₹ Crore) | H25: 📊 EBITDA vs Operating Cash Flow (₹ Crore)
B39: 📈 ROE & ROCE Trend (%) | H39: 📈 Margin Trends (%)
B53: 💡 Key Analyst Insights
B54: ▶ Revenue CAGR | C54: TCS delivered a 10.0% revenue CAGR over 10 years, growing from ₹1.09L Cr (FY16) to ₹2.55L Cr (FY25) — consistent industry-beating growth.
B55: ▶ Profitability | C55: Net profit CAGR of 8.0% with margins consistently above 18%, demonstrating superior cost discipline in a people-intensive business.
B56: ▶ Return Quality | C56: ROE expanded from 29.9% (FY16) to 47.3% (FY25) — a 17pp improvement — driven by capital-efficient operations and buybacks.
A70: Year | B70: ▶ Cash Generation | C70: CFO grew from ₹19,109 Cr to ₹48,908 Cr (+11.0% CAGR). CFO/Net Profit consistently above 1x confirms high earnings quality.
A71: 2016 | B71: ▶ Valuation | C71: Stock rose from ₹1,260 (FY16) to ₹3,606 (FY25), delivering ~186% absolute return. Near-term correction from ₹3,876 (FY24) peak warrants monitoring.
A72: 2017 | B72: 123104 | C72: 25826 | D72: 36104 | E72: 25067 | F72: 26.12 | G72: 35.73 | H72: 20.98 | I72: 29.33 | J72: 1424.58
A73: 2018 | B73: Source: TCS Annual Reports FY2016–FY2025 | All figures in ₹ Crore unless stated | Prepared by: [Your Name]
A74: 2019 | B74: 156949 | C74: 32340 | D74: 46594 | E74: 32369 | F74: 33.11 | G74: 41.8 | H74: 20.61 | I74: 29.69 | J74: 1826.1
A75: 2020 | B75: 164177 | C75: 32430 | D75: 48330 | E75: 38802 | F75: 35.46 | G75: 45.08 | H75: 19.75 | I75: 29.44 | J75: 3177.85
A76: 2021 | B76: 191754 | C76: 38327 | D76: 56953 | E76: 39949 | F76: 38.63 | G76: 49.97 | H76: 19.99 | I76: 29.7 | J76: 3739.95
A77: 2022 | B77: 225458 | C77: 42147 | D77: 62552 | E77: 41965 | F77: 42.97 | G77: 55.28 | H77: 18.69 | I77: 27.74 | J77: 3205.9
A78: 2023 | B78: 240893 | C78: 45908 | D78: 67569 | E78: 44338 | F78: 47.12 | G78: 60.21 | H78: 19.06 | I78: 28.05 | J78: 3876.3
A79: 2024 | B79: 255324 | C79: 48553 | D79: 71125 | E79: 48908 | F79: 47.32 | G79: 59.69 | H79: 19.01 | I79: 27.86 | J79: 3606.15
A80: 2025

Sheet KPI
A2: # | B2: KPI Metric | C2: FY25 Actual | D2: FY25 Target | E2: Variance % | F2: Status
B3: Revenue (₹ Crore) | C3: =HistoricalFS!L6 -> 255324 | D3: 250000 | E3: =(C3-D3)/D3 -> 0.021296 | F3: =IF(E3>=0.02,"✅ On Target",IF(E3>=-0.02,"🟡 Near Target","🔴 Off Target")) -> ✅ On Target
B4: Net Profit (₹ Crore) | C4: =HistoricalFS!L33 -> 44835 | D4: 46000 | E4: =(C4-D4)/D4 -> -0.025326087 | F4: =IF(E4>=0.02,"✅ On Target",IF(E4>=-0.02,"🟡 Near Target","🔴 Off Target")) -> 🔴 Off Target
B5: EBITDA (₹ Crore | C5: =HistoricalFS!L18 -> 67407 | D5: 69000 | E5: =(C5-D5)/D5 -> -0.023086957 | F5: =IF(E5>=0.02,"✅ On Target",IF(E5>=-0.02,"🟡 Near Target","🔴 Off Target")) -> 🔴 Off Target
B6: Operating Cash Flow | C6: =HistoricalFS!L78 -> 47052 | D6: 46000 | E6: =(C6-D6)/D6 -> 0.022869565 | F6: =IF(E6>=0.02,"✅ On Target",IF(E6>=-0.02,"🟡 Near Target","🔴 Off Target")) -> ✅ On Target
B7: Net Profit Margin % | C7: =HistoricalFS!L34 -> 0.17560041 | D7: 0.185 | E7: =(C7-D7)/D7 -> -0.050808575 | F7: =IF(E7>=0.02,"✅ On Target",IF(E7>=-0.02,"🟡 Near Target","🔴 Off Target")) -> 🔴 Off Target
B8: EBITDA Margin % | C8: =HistoricalFS!L19 -> 0.26400573 | D8: 0.285 | E8: =(C8-D8)/D8 -> -0.073664092 | F8: =IF(E8>=0.02,"✅ On Target",IF(E8>=-0.02,"🟡 Near Target","🔴 Off Target")) -> 🔴 Off Target
B9: Return on Equity % | C9: ='Ratio Analysis'!L23 -> 0.47316265 | D9: 0.44 | E9: =(C9-D9)/D9 -> 0.075369658 | F9: =IF(E9>=0.02,"✅ On Target",IF(E9>=-0.02,"🟡 Near Target","🔴 Off Target")) -> ✅ On Target
B10: Return on Capital Emp. % | C10: ='Ratio Analysis'!L21 -> 0.59689096 | D10: 0.56 | E10: =(C10-D10)/D10 -> 0.065876719 | F10: =IF(E10>=0.02,"✅ On Target",IF(E10>=-0.02,"🟡 Near Target","🔴 Off Target")) -> ✅ On Target
E12: Overall Score | F12: =COUNTIF(F3:F10,"✅ On Target") & " / 8 KPIs On Target" -> 4 / 8 KPIs On Target

Sheet HistoricalFS
B2: ="Historical Financial Statement-"&'Data Sheet'!B1 -> Historical Financial Statement-TATA CONSULTANCY SERVICES LTD
B3: Years | C3: ='Data Sheet'!B16 -> 42460 | D3: ='Data Sheet'!C16 -> 42825 | E3: ='Data Sheet'!D16 -> 43190 | F3: ='Data Sheet'!E16 -> 43555 | G3: ='Data Sheet'!F16 -> 43921 | H3: ='Data Sheet'!G16 -> 44286 | I3: ='Data Sheet'!H16 -> 44651 | J3: ='Data Sheet'!I16 -> 45016 | ... L3: ='Data Sheet'!K16 -> 45747 | M3: LTM
A5: # | B5: Income Statement
B6: Sales | C6: =IFERROR('Data Sheet'!B17,0) -> 108646 | D6: =IFERROR('Data Sheet'!C17,0) -> 117966 | E6: =IFERROR('Data Sheet'!D17,0) -> 123104 | F6: =IFERROR('Data Sheet'!E17,0) -> 146463 | G6: =IFERROR('Data Sheet'!F17,0) -> 156949 | H6: =IFERROR('Data Sheet'!G17,0) -> 164177 | I6: =IFERROR('Data Sheet'!H17,0) -> 191754 | J6: =IFERROR('Data Sheet'!I17,0) -> 225458 | ... L6: =IFERROR('Data Sheet'!K17,0) -> 255324 | M6: =IFERROR(SUM('Data Sheet'!H41:K41),0) -> 260802
B7: Sales Growth | C7: - | D7: =D6/C6-1 -> 0.085783186 | E7: =E6/D6-1 -> 0.043554923 | F7: =F6/E6-1 -> 0.18975013 | G7: =G6/F6-1 -> 0.071594874 | H7: =H6/G6-1 -> 0.046053177 | I7: =I6/H6-1 -> 0.16797115 | J7: =J6/I6-1 -> 0.17576687 | K7: =K6/J6-1 -> 0.068460645 | ... M7: =M6/L6-1 -> 0.021455092
B9: COGS | C9: =IFERROR(SUM('Data Sheet'!B18,'Data Sheet'!B20:B22)-1*'Data Sheet'!B19,0) -> 57919 | D9: =IFERROR(SUM('Data Sheet'!C18,'Data Sheet'!C20:C22)-1*'Data Sheet'!C19,0) -> 64429 | E9: =IFERROR(SUM('Data Sheet'!D18,'Data Sheet'!D20:D22)-1*'Data Sheet'!D19,0) -> 69096 | F9: =IFERROR(SUM('Data Sheet'!E18,'Data Sheet'!E20:E22)-1*'Data Sheet'!E19,0) -> 80516 | G9: =IFERROR(SUM('Data Sheet'!F18,'Data Sheet'!F20:F22)-1*'Data Sheet'!F19,0) -> 87857 | H9: =IFERROR(SUM('Data Sheet'!G18,'Data Sheet'!G20:G22)-1*'Data Sheet'!G19,0) -> 93276 | I9: =IFERROR(SUM('Data Sheet'!H18,'Data Sheet'!H20:H22)-1*'Data Sheet'!H19,0) -> 108717 | J9: =IFERROR(SUM('Data Sheet'!I18,'Data Sheet'!I20:I22)-1*'Data Sheet'!I19,0) -> 129403 | ... L9: =IFERROR(SUM('Data Sheet'!K18,'Data Sheet'!K20:K22)-1*'Data Sheet'!K19,0) -> 157436 | M9: =IFERROR(SUM('Data Sheet'!H42:K42),0) -> 190700
B10: COGS%Sales | C10: =C9/C6 -> 0.53309832 | D10: =D9/D6 -> 0.54616584 | E10: =E9/E6 -> 0.56128152 | F10: =F9/F6 -> 0.54973611 | G10: =G9/G6 -> 0.55978057 | H10: =H9/H6 -> 0.56814292 | I10: =I9/I6 -> 0.56696079 | J10: =J9/J6 -> 0.57395612 | ... M10: =M9/M6 -> 0.73120605
B12: Gross Profit | C12: =C6-C9 -> 50727 | D12: =D6-D9 -> 53537 | E12: =E6-E9 -> 54008 | F12: =F6-F9 -> 65947 | G12: =G6-G9 -> 69092 | H12: =H6-H9 -> 70901 | I12: =I6-I9 -> 83037 | J12: =J6-J9 -> 96055 | ... M12: =M6-M9 -> 70102
B13: Gross Margin | C13: =C12/C6 -> 0.46690168 | D13: =D12/D6 -> 0.45383416 | E13: =E12/E6 -> 0.43871848 | F13: =F12/F6 -> 0.45026389 | G13: =G12/G6 -> 0.44021943 | H13: =H12/H6 -> 0.43185708 | I13: =I12/I6 -> 0.43303921 | J13: =J12/J6 -> 0.42604388 | ... M13: =M12/M6 -> 0.26879395
B15: S&G Expenses | C15: =IFERROR(SUM('Data Sheet'!B23:B24),0) -> 20050 | D15: =IFERROR(SUM('Data Sheet'!C23:C24),0) -> 21226 | E15: =IFERROR(SUM('Data Sheet'!D23:D24),0) -> 21492 | F15: =IFERROR(SUM('Data Sheet'!E23:E24),0) -> 26441 | G15: =IFERROR(SUM('Data Sheet'!F23:F24),0) -> 26983 | H15: =IFERROR(SUM('Data Sheet'!G23:G24),0) -> 24355 | I15: =IFERROR(SUM('Data Sheet'!H23:H24),0) -> 29980 | J15: =IFERROR(SUM('Data Sheet'!I23:I24),0) -> 36796 | ... L15: =IFERROR(SUM('Data Sheet'!K23:K24),0) -> 30481
B16: S&G Exp%Sales | C16: =C15/C6 -> 0.1845443 | D16: =D15/D6 -> 0.1799332 | E16: =E15/E6 -> 0.17458409 | F16: =F15/F6 -> 0.18053024 | G16: =G15/G6 -> 0.17192209 | H16: =H15/H6 -> 0.14834599 | I16: =I15/I6 -> 0.15634615 | J16: =J15/J6 -> 0.16320556 | ... M16: =M15/M6 -> 0
B18: EBITDA | C18: =C12-C15 -> 30677 | D18: =D12-D15 -> 32311 | E18: =E12-E15 -> 32516 | F18: =F12-F15 -> 39506 | G18: =G12-G15 -> 42109 | H18: =H12-H15 -> 46546 | I18: =I12-I15 -> 53057 | J18: =J12-J15 -> 59259 | ... L18: =L12-L15 -> 67407 | M18: =IFERROR(SUM('Data Sheet'!H49:K49),0) -> 70102
B19: EBITDA Margins | C19: =C18/C6 -> 0.28235738 | D19: =D18/D6 -> 0.27390095 | E19: =E18/E6 -> 0.26413439 | F19: =F18/F6 -> 0.26973365 | G19: =G18/G6 -> 0.26829734 | H19: =H18/H6 -> 0.28351109 | I19: =I18/I6 -> 0.27669305 | J19: =J18/J6 -> 0.26283831 | ... M19: =M18/M6 -> 0.26879395
B21: Interest | C21: =IFERROR('Data Sheet'!B27,0) -> 33 | D21: =IFERROR('Data Sheet'!C27,0) -> 32 | E21: =IFERROR('Data Sheet'!D27,0) -> 52 | F21: =IFERROR('Data Sheet'!E27,0) -> 198 | G21: =IFERROR('Data Sheet'!F27,0) -> 924 | H21: =IFERROR('Data Sheet'!G27,0) -> 637 | I21: =IFERROR('Data Sheet'!H27,0) -> 784 | J21: =IFERROR('Data Sheet'!I27,0) -> 779 | ... L21: =IFERROR('Data Sheet'!K27,0) -> 796 | M21: =IFERROR(SUM('Data Sheet'!H45:K45),0) -> 1189
B22: Interest%Sales | C22: =C21/C6 -> 0.00030373875 | D22: =D21/D6 -> 0.0002712646 | E22: =E21/E6 -> 0.00042240707 | F22: =F21/F6 -> 0.0013518773 | G22: =G21/G6 -> 0.0058872627 | H22: =H21/H6 -> 0.0038799588 | I22: =I21/I6 -> 0.0040885718 | J22: =J21/J6 -> 0.003455189 | ... M22: =M21/M6 -> 0.0045590141
B24: Depreciation | C24: =IFERROR('Data Sheet'!B26,0) -> 1888 | D24: =IFERROR('Data Sheet'!C26,0) -> 1987 | E24: =IFERROR('Data Sheet'!D26,0) -> 2014 | F24: =IFERROR('Data Sheet'!E26,0) -> 2056 | G24: =IFERROR('Data Sheet'!F26,0) -> 3529 | H24: =IFERROR('Data Sheet'!G26,0) -> 4065 | I24: =IFERROR('Data Sheet'!H26,0) -> 4604 | J24: =IFERROR('Data Sheet'!I26,0) -> 5022 | ... L24: =IFERROR('Data Sheet'!K26,0) -> 5242 | M24: =IFERROR(SUM('Data Sheet'!H44:K44),0) -> 5533
B25: Depreciation%Sales | C25: =C24/C6 -> 0.017377538 | D25: =D24/D6 -> 0.016843836 | E25: =E24/E6 -> 0.016360151 | F25: =F24/F6 -> 0.014037675 | G25: =G24/G6 -> 0.022485011 | H25: =H24/H6 -> 0.024759863 | I25: =I24/I6 -> 0.024009929 | J25: =J24/J6 -> 0.022274659 | ... M25: =M24/M6 -> 0.021215328
B27: Earnings Before Tax | C27: =C18-SUM(C21,C24) -> 28756 | D27: =D18-SUM(D21,D24) -> 30292 | E27: =E18-SUM(E21,E24) -> 30450 | F27: =F18-SUM(F21,F24) -> 37252 | G27: =G18-SUM(G21,G24) -> 37656 | H27: =H18-SUM(H21,H24) -> 41844 | I27: =I18-SUM(I21,I24) -> 47669 | J27: =J18-SUM(J21,J24) -> 53458 | ... M27: =M18-SUM(M21,M24) -> 63380
B28: EBT%Sales | C28: =C27/C6 -> 0.2646761 | D28: =D27/D6 -> 0.25678585 | E28: =E27/E6 -> 0.24735183 | F28: =F27/F6 -> 0.2543441 | G28: =G27/G6 -> 0.23992507 | H28: =H27/H6 -> 0.25487127 | I28: =I27/I6 -> 0.24859455 | J28: =J27/J6 -> 0.23710846 | ... M28: =M27/M6 -> 0.24301961
B30: Tax | C30: =IFERROR('Data Sheet'!B29,0) -> 7502 | D30: =IFERROR('Data Sheet'!C29,0) -> 8156 | E30: =IFERROR('Data Sheet'!D29,0) -> 8212 | F30: =IFERROR('Data Sheet'!E29,0) -> 10001 | G30: =IFERROR('Data Sheet'!F29,0) -> 9801 | H30: =IFERROR('Data Sheet'!G29,0) -> 11198 | I30: =IFERROR('Data Sheet'!H29,0) -> 13238 | J30: =IFERROR('Data Sheet'!I29,0) -> 14604 | ... L30: =IFERROR('Data Sheet'!K29,0) -> 16534 | M30: =IFERROR(SUM('Data Sheet'!H47:K47),0) -> 15564
B31: Effective Tax Rate | C31: =C30/C27 -> 0.26088468 | D31: =D30/D27 -> 0.26924601 | E31: =E30/E27 -> 0.26968801 | F31: =F30/F27 -> 0.26846881 | G31: =G30/G27 -> 0.26027725 | H31: =H30/H27 -> 0.26761304 | I31: =I30/I27 -> 0.27770669 | J31: =J30/J27 -> 0.27318643 | ... M31: =M30/M27 -> 0.24556642
B33: Net Profit | C33: =C27-C30 -> 21254 | D33: =D27-D30 -> 22136 | E33: =E27-E30 -> 22238 | F33: =F27-F30 -> 27251 | G33: =G27-G30 -> 27855 | H33: =H27-H30 -> 30646 | I33: =I27-I30 -> 34431 | J33: =J27-J30 -> 38854 | ... M33: =M27-M30 -> 47816
B34: Net Profit Margin | C34: =C33/C6 -> 0.19562616 | D34: =D33/D6 -> 0.18764729 | E34: =E33/E6 -> 0.18064401 | F34: =F33/F6 -> 0.18606064 | G34: =G33/G6 -> 0.17747803 | H34: =H33/H6 -> 0.18666439 | I34: =I33/I6 -> 0.17955818 | J34: =J33/J6 -> 0.17233365 | ... M34: =M33/M6 -> 0.18334215
B36: No of Equity Shares | C36: =IFERROR('Data Sheet'!B92,0) -> 394.09 | D36: =IFERROR('Data Sheet'!C92,0) -> 394.09 | E36: =IFERROR('Data Sheet'!D92,0) -> 382.86 | F36: =IFERROR('Data Sheet'!E92,0) -> 375.24 | G36: =IFERROR('Data Sheet'!F92,0) -> 375.24 | H36: =IFERROR('Data Sheet'!G92,0) -> 369.91 | I36: =IFERROR('Data Sheet'!H92,0) -> 365.91 | J36: =IFERROR('Data Sheet'!I92,0) -> 365.91 | ... L36: =IFERROR('Data Sheet'!K92,0) -> 361.81
B38: EPS | C38: =IFERROR(C33/C36,0) -> 53.931843 | D38: =IFERROR(D33/D36,0) -> 56.16991 | E38: =IFERROR(E33/E36,0) -> 58.083895 | F38: =IFERROR(F33/F36,0) -> 72.622855 | G38: =IFERROR(G33/G36,0) -> 74.232491 | H38: =IFERROR(H33/H36,0) -> 82.847179 | I38: =IFERROR(I33/I36,0) -> 94.096909 | J38: =IFERROR(J33/J36,0) -> 106.18458 | ... L38: =IFERROR(L33/L36,0) -> 123.91863
B39: EPS Growth % | D39: =IFERROR(D38/C38-1,0) -> 0.041498071 | E39: =IFERROR(E38/D38-1,0) -> 0.034074907 | F39: =IFERROR(F38/E38-1,0) -> 0.25030966 | G39: =IFERROR(G38/F38-1,0) -> 0.022164324 | H39: =IFERROR(H38/G38-1,0) -> 0.1160501 | I39: =IFERROR(I38/H38-1,0) -> 0.13578893 | J39: =IFERROR(J38/I38-1,0) -> 0.12845982 | K39: =IFERROR(K38/J38-1,0) -> 0.10974768 | L39: =IFERROR(L38/K38-1,0) -> 0.051600797
B41: Dividend Per Share | C41: =IFERROR('Data Sheet'!B31/HistoricalFS!C36,0) -> 21.745033 | D41: =IFERROR('Data Sheet'!C31/HistoricalFS!D36,0) -> 23.494633 | E41: =IFERROR('Data Sheet'!D31/HistoricalFS!E36,0) -> 24.943844 | F41: =IFERROR('Data Sheet'!E31/HistoricalFS!F36,0) -> 29.980812 | G41: =IFERROR('Data Sheet'!F31/HistoricalFS!G36,0) -> 72.95331 | H41: =IFERROR('Data Sheet'!G31/HistoricalFS!H36,0) -> 38.009245 | I41: =IFERROR('Data Sheet'!H31/HistoricalFS!I36,0) -> 43.010576 | J41: =IFERROR('Data Sheet'!I31/HistoricalFS!J36,0) -> 115.02829 | ... L41: =IFERROR('Data Sheet'!K31/HistoricalFS!L36,0) -> 126.06617
B42: Dividend Payout Ratio | C42: =IFERROR(C41/C38,0) -> 0.40319469 | D42: =IFERROR(D41/D38,0) -> 0.41827792 | E42: =IFERROR(E41/E38,0) -> 0.42944509 | F42: =IFERROR(F41/F38,0) -> 0.41282889 | G42: =IFERROR(G41/G38,0) -> 0.98276791 | H42: =IFERROR(H41/H38,0) -> 0.45878744 | I42: =IFERROR(I41/I38,0) -> 0.45708809 | J42: =IFERROR(J41/J38,0) -> 1.0832861 | ... L42: =IFERROR(L41/L38,0) -> 1.0173302
B44: Retained Earnings | C44: =IFERROR(IF(C38>C41,1-C42,0),0) -> 0.59680531 | D44: =IFERROR(IF(D38>D41,1-D42,0),0) -> 0.58172208 | E44: =IFERROR(IF(E38>E41,1-E42,0),0) -> 0.57055491 | F44: =IFERROR(IF(F38>F41,1-F42,0),0) -> 0.58717111 | G44: =IFERROR(IF(G38>G41,1-G42,0),0) -> 0.017232095 | H44: =IFERROR(IF(H38>H41,1-H42,0),0) -> 0.54121256 | I44: =IFERROR(IF(I38>I41,1-I42,0),0) -> 0.54291191 | J44: =IFERROR(IF(J38>J41,1-J42,0),0) -> 0 | ... L44: =IFERROR(IF(L38>L41,1-L42,0),0) -> 0
A46: # | B46: Balance Sheet
B47: Equity Share Capital | C47: =IFERROR('Data Sheet'!B56,0) -> 197 | D47: =IFERROR('Data Sheet'!C56,0) -> 197 | E47: =IFERROR('Data Sheet'!D56,0) -> 191 | F47: =IFERROR('Data Sheet'!E56,0) -> 375 | G47: =IFERROR('Data Sheet'!F56,0) -> 375 | H47: =IFERROR('Data Sheet'!G56,0) -> 370 | I47: =IFERROR('Data Sheet'!H56,0) -> 366 | J47: =IFERROR('Data Sheet'!I56,0) -> 366 | ... L47: =IFERROR('Data Sheet'!K56,0) -> 362
B48: Reserves | C48: =IFERROR('Data Sheet'!B57,0) -> 70875 | D48: =IFERROR('Data Sheet'!C57,0) -> 86017 | E48: =IFERROR('Data Sheet'!D57,0) -> 84937 | F48: =IFERROR('Data Sheet'!E57,0) -> 89071 | G48: =IFERROR('Data Sheet'!F57,0) -> 83751 | H48: =IFERROR('Data Sheet'!G57,0) -> 86063 | I48: =IFERROR('Data Sheet'!H57,0) -> 88773 | J48: =IFERROR('Data Sheet'!I57,0) -> 90058 | ... L48: =IFERROR('Data Sheet'!K57,0) -> 94394
B49: Borrowings | C49: =IFERROR('Data Sheet'!B58,0) -> 245 | D49: =IFERROR('Data Sheet'!C58,0) -> 289 | E49: =IFERROR('Data Sheet'!D58,0) -> 247 | F49: =IFERROR('Data Sheet'!E58,0) -> 62 | G49: =IFERROR('Data Sheet'!F58,0) -> 8174 | H49: =IFERROR('Data Sheet'!G58,0) -> 7795 | I49: =IFERROR('Data Sheet'!H58,0) -> 7818 | J49: =IFERROR('Data Sheet'!I58,0) -> 7688 | ... L49: =IFERROR('Data Sheet'!K58,0) -> 9392
B50: Other Liabilities | C50: =IFERROR('Data Sheet'!B59,0) -> 16974 | D50: =IFERROR('Data Sheet'!C59,0) -> 15830 | E50: =IFERROR('Data Sheet'!D59,0) -> 19751 | F50: =IFERROR('Data Sheet'!E59,0) -> 24393 | G50: =IFERROR('Data Sheet'!F59,0) -> 27827 | H50: =IFERROR('Data Sheet'!G59,0) -> 35764 | I50: =IFERROR('Data Sheet'!H59,0) -> 43967 | J50: =IFERROR('Data Sheet'!I59,0) -> 44747 | ... L50: =IFERROR('Data Sheet'!K59,0) -> 54501
B51: Total Liabilities | C51: =IFERROR(SUM(C47:C50),0) -> 88291 | D51: =IFERROR(SUM(D47:D50),0) -> 102333 | E51: =IFERROR(SUM(E47:E50),0) -> 105126 | F51: =IFERROR(SUM(F47:F50),0) -> 113901 | G51: =IFERROR(SUM(G47:G50),0) -> 120127 | H51: =IFERROR(SUM(H47:H50),0) -> 129992 | I51: =IFERROR(SUM(I47:I50),0) -> 140924 | J51: =IFERROR(SUM(J47:J50),0) -> 142859 | ... L51: =IFERROR(SUM(L47:L50),0) -> 158649
B53: Fixed Assets Net Block | C53: =IFERROR('Data Sheet'!B61,0) -> 11774 | D53: =IFERROR('Data Sheet'!C61,0) -> 11701 | E53: =IFERROR('Data Sheet'!D61,0) -> 11973 | F53: =IFERROR('Data Sheet'!E61,0) -> 12290 | G53: =IFERROR('Data Sheet'!F61,0) -> 20928 | H53: =IFERROR('Data Sheet'!G61,0) -> 21021 | I53: =IFERROR('Data Sheet'!H61,0) -> 21298 | J53: =IFERROR('Data Sheet'!I61,0) -> 20515 | ... L53: =IFERROR('Data Sheet'!K61,0) -> 23053
B54: Capital Work in Progress | C54: =IFERROR('Data Sheet'!B62,0) -> 1670 | D54: =IFERROR('Data Sheet'!C62,0) -> 1541 | E54: =IFERROR('Data Sheet'!D62,0) -> 1278 | F54: =IFERROR('Data Sheet'!E62,0) -> 963 | G54: =IFERROR('Data Sheet'!F62,0) -> 906 | H54: =IFERROR('Data Sheet'!G62,0) -> 926 | I54: =IFERROR('Data Sheet'!H62,0) -> 1205 | J54: =IFERROR('Data Sheet'!I62,0) -> 1234 | ... L54: =IFERROR('Data Sheet'!K62,0) -> 1546
B55: Investments | C55: =IFERROR('Data Sheet'!B63,0) -> 22822 | D55: =IFERROR('Data Sheet'!C63,0) -> 41980 | E55: =IFERROR('Data Sheet'!D63,0) -> 36008 | F55: =IFERROR('Data Sheet'!E63,0) -> 29330 | G55: =IFERROR('Data Sheet'!F63,0) -> 26356 | H55: =IFERROR('Data Sheet'!G63,0) -> 29373 | I55: =IFERROR('Data Sheet'!H63,0) -> 30485 | J55: =IFERROR('Data Sheet'!I63,0) -> 37163 | ... L55: =IFERROR('Data Sheet'!K63,0) -> 30964
B56: Other Assets | C56: =IFERROR((('Data Sheet'!B64)-SUM('Data Sheet'!B66:B68)),0) -> 21148 | D56: =IFERROR((('Data Sheet'!C64)-SUM('Data Sheet'!C66:C68)),0) -> 20324 | E56: =IFERROR((('Data Sheet'!D64)-SUM('Data Sheet'!D66:D68)),0) -> 23737 | F56: =IFERROR((('Data Sheet'!E64)-SUM('Data Sheet'!E66:E68)),0) -> 31114 | G56: =IFERROR((('Data Sheet'!F64)-SUM('Data Sheet'!F66:F68)),0) -> 31734 | H56: =IFERROR((('Data Sheet'!G64)-SUM('Data Sheet'!G66:G68)),0) -> 39256 | I56: =IFERROR((('Data Sheet'!H64)-SUM('Data Sheet'!H66:H68)),0) -> 27885 | J56: =IFERROR((('Data Sheet'!I64)-SUM('Data Sheet'!I66:I68)),0) -> 22933 | ... L56: =IFERROR((('Data Sheet'!K64)-SUM('Data Sheet'!K66:K68)),0) -> 28556
B57: Total Non Current Assets | C57: =IFERROR(SUM(C53:C56),0) -> 57414 | D57: =IFERROR(SUM(D53:D56),0) -> 75546 | E57: =IFERROR(SUM(E53:E56),0) -> 72996 | F57: =IFERROR(SUM(F53:F56),0) -> 73697 | G57: =IFERROR(SUM(G53:G56),0) -> 79924 | H57: =IFERROR(SUM(H53:H56),0) -> 90576 | I57: =IFERROR(SUM(I53:I56),0) -> 80873 | J57: =IFERROR(SUM(J53:J56),0) -> 81845 | ... L57: =IFERROR(SUM(L53:L56),0) -> 84119
...

Sheet Ratio Analysis
B2: ="Ratio Analysis-"&'Data Sheet'!B1 -> Ratio Analysis-TATA CONSULTANCY SERVICES LTD
B3: Years | C3: ='Data Sheet'!B16 -> 42460 | D3: ='Data Sheet'!C16 -> 42825 | E3: ='Data Sheet'!D16 -> 43190 | F3: ='Data Sheet'!E16 -> 43555 | G3: ='Data Sheet'!F16 -> 43921 | H3: ='Data Sheet'!G16 -> 44286 | I3: ='Data Sheet'!H16 -> 44651 | J3: ='Data Sheet'!I16 -> 45016 | ... L3: ='Data Sheet'!K16 -> 45747 | M3: Trend | N3: Mean | O3: Median
B5: Sales Growth | D5: =IFERROR(HistoricalFS!D7,0) -> 0.085783186 | E5: =IFERROR(HistoricalFS!E7,0) -> 0.043554923 | F5: =IFERROR(HistoricalFS!F7,0) -> 0.18975013 | G5: =IFERROR(HistoricalFS!G7,0) -> 0.071594874 | H5: =IFERROR(HistoricalFS!H7,0) -> 0.046053177 | I5: =IFERROR(HistoricalFS!I7,0) -> 0.16797115 | J5: =IFERROR(HistoricalFS!J7,0) -> 0.17576687 | K5: =IFERROR(HistoricalFS!K7,0) -> 0.068460645 | L5: =IFERROR(HistoricalFS!L7,0) -> 0.059906265 | N5: =IFERROR(AVERAGE(D5:L5),0) -> 0.10098236 | O5: =IFERROR(MEDIAN(D5:L5),0) -> 0.071594874
B6: EBITDA Growth | D6: =IFERROR((HistoricalFS!D18/HistoricalFS!C18-1),0) -> 0.053264661 | E6: =IFERROR((HistoricalFS!E18/HistoricalFS!D18-1),0) -> 0.0063445885 | F6: =IFERROR((HistoricalFS!F18/HistoricalFS!E18-1),0) -> 0.21497109 | G6: =IFERROR((HistoricalFS!G18/HistoricalFS!F18-1),0) -> 0.065888726 | H6: =IFERROR((HistoricalFS!H18/HistoricalFS!G18-1),0) -> 0.1053694 | I6: =IFERROR((HistoricalFS!I18/HistoricalFS!H18-1),0) -> 0.13988313 | J6: =IFERROR((HistoricalFS!J18/HistoricalFS!I18-1),0) -> 0.11689315 | K6: =IFERROR((HistoricalFS!K18/HistoricalFS!J18-1),0) -> 0.084999747 | L6: =IFERROR((HistoricalFS!L18/HistoricalFS!K18-1),0) -> 0.048385592 | N6: =IFERROR(AVERAGE(D6:L6),0) -> 0.092888898 | O6: =IFERROR(MEDIAN(D6:L6),0) -> 0.084999747
B7: EBIT Growth | D7: =IFERROR((HistoricalFS!D27/HistoricalFS!C27-1),0) -> 0.053414939 | E7: =IFERROR((HistoricalFS!E27/HistoricalFS!D27-1),0) -> 0.0052158986 | F7: =IFERROR((HistoricalFS!F27/HistoricalFS!E27-1),0) -> 0.22338259 | G7: =IFERROR((HistoricalFS!G27/HistoricalFS!F27-1),0) -> 0.010845055 | H7: =IFERROR((HistoricalFS!H27/HistoricalFS!G27-1),0) -> 0.11121734 | I7: =IFERROR((HistoricalFS!I27/HistoricalFS!H27-1),0) -> 0.13920753 | J7: =IFERROR((HistoricalFS!J27/HistoricalFS!I27-1),0) -> 0.12144161 | K7: =IFERROR((HistoricalFS!K27/HistoricalFS!J27-1),0) -> 0.094934341 | L7: =IFERROR((HistoricalFS!L27/HistoricalFS!K27-1),0) -> 0.048451301 | N7: =IFERROR(AVERAGE(D7:L7),0) -> 0.089790067 | O7: =IFERROR(MEDIAN(D7:L7),0) -> 0.094934341
B8: Net Profit Growth | D8: =IFERROR((HistoricalFS!D33/HistoricalFS!C33-1),0) -> 0.041498071 | E8: =IFERROR((HistoricalFS!E33/HistoricalFS!D33-1),0) -> 0.0046078786 | F8: =IFERROR((HistoricalFS!F33/HistoricalFS!E33-1),0) -> 0.22542495 | G8: =IFERROR((HistoricalFS!G33/HistoricalFS!F33-1),0) -> 0.022164324 | H8: =IFERROR((HistoricalFS!H33/HistoricalFS!G33-1),0) -> 0.10019745 | I8: =IFERROR((HistoricalFS!I33/HistoricalFS!H33-1),0) -> 0.12350715 | J8: =IFERROR((HistoricalFS!J33/HistoricalFS!I33-1),0) -> 0.12845982 | K8: =IFERROR((HistoricalFS!K33/HistoricalFS!J33-1),0) -> 0.097313018 | L8: =IFERROR((HistoricalFS!L33/HistoricalFS!K33-1),0) -> 0.051600797 | N8: =IFERROR(AVERAGE(D8:L8),0) -> 0.088308161 | O8: =IFERROR(MEDIAN(D8:L8),0) -> 0.097313018
B9: Dividend Growth | D9: =IFERROR((HistoricalFS!D41/HistoricalFS!C41-1),0) -> 0.08045977 | E9: =IFERROR((HistoricalFS!E41/HistoricalFS!D41-1),0) -> 0.061682619 | F9: =IFERROR((HistoricalFS!F41/HistoricalFS!E41-1),0) -> 0.20193233 | G9: =IFERROR((HistoricalFS!G41/HistoricalFS!F41-1),0) -> 1.4333333 | H9: =IFERROR((HistoricalFS!H41/HistoricalFS!G41-1),0) -> -0.47899217 | I9: =IFERROR((HistoricalFS!I41/HistoricalFS!H41-1),0) -> 0.13158196 | J9: =IFERROR((HistoricalFS!J41/HistoricalFS!I41-1),0) -> 1.6744186 | K9: =IFERROR((HistoricalFS!K41/HistoricalFS!J41-1),0) -> -0.36504022 | L9: =IFERROR((HistoricalFS!L41/HistoricalFS!K41-1),0) -> 0.7260274 | N9: =IFERROR(AVERAGE(D9:L9),0) -> 0.38504485 | O9: =IFERROR(MEDIAN(D9:L9),0) -> 0.13158196
B11: Gross Margin | C11: =IFERROR(HistoricalFS!C13,0) -> 0.46690168 | D11: =IFERROR(HistoricalFS!D13,0) -> 0.45383416 | E11: =IFERROR(HistoricalFS!E13,0) -> 0.43871848 | F11: =IFERROR(HistoricalFS!F13,0) -> 0.45026389 | G11: =IFERROR(HistoricalFS!G13,0) -> 0.44021943 | H11: =IFERROR(HistoricalFS!H13,0) -> 0.43185708 | I11: =IFERROR(HistoricalFS!I13,0) -> 0.43303921 | J11: =IFERROR(HistoricalFS!J13,0) -> 0.42604388 | ... L11: =IFERROR(HistoricalFS!L13,0) -> 0.38338738 | N11: =IFERROR(AVERAGE(C11:L11),0) -> 0.43271827 | O11: =IFERROR(MEDIAN(C11:L11),0) -> 0.43587884
B12: EBITDA Margin | C12: =IFERROR(HistoricalFS!C19,0) -> 0.28235738 | D12: =IFERROR(HistoricalFS!D19,0) -> 0.27390095 | E12: =IFERROR(HistoricalFS!E19,0) -> 0.26413439 | F12: =IFERROR(HistoricalFS!F19,0) -> 0.26973365 | G12: =IFERROR(HistoricalFS!G19,0) -> 0.26829734 | H12: =IFERROR(HistoricalFS!H19,0) -> 0.28351109 | I12: =IFERROR(HistoricalFS!I19,0) -> 0.27669305 | J12: =IFERROR(HistoricalFS!J19,0) -> 0.26283831 | ... L12: =IFERROR(HistoricalFS!L19,0) -> 0.26400573 | N12: =IFERROR(AVERAGE(C12:L12),0) -> 0.27123788 | O12: =IFERROR(MEDIAN(C12:L12),0) -> 0.2690155
B13: EBIT Margin | C13: =IFERROR(((HistoricalFS!C18-HistoricalFS!C24)/HistoricalFS!C6),0) -> 0.26497984 | D13: =IFERROR(((HistoricalFS!D18-HistoricalFS!D24)/HistoricalFS!D6),0) -> 0.25705712 | E13: =IFERROR(((HistoricalFS!E18-HistoricalFS!E24)/HistoricalFS!E6),0) -> 0.24777424 | F13: =IFERROR(((HistoricalFS!F18-HistoricalFS!F24)/HistoricalFS!F6),0) -> 0.25569598 | G13: =IFERROR(((HistoricalFS!G18-HistoricalFS!G24)/HistoricalFS!G6),0) -> 0.24581233 | H13: =IFERROR(((HistoricalFS!H18-HistoricalFS!H24)/HistoricalFS!H6),0) -> 0.25875123 | I13: =IFERROR(((HistoricalFS!I18-HistoricalFS!I24)/HistoricalFS!I6),0) -> 0.25268313 | J13: =IFERROR(((HistoricalFS!J18-HistoricalFS!J24)/HistoricalFS!J6),0) -> 0.24056365 | ... L13: =IFERROR(((HistoricalFS!L18-HistoricalFS!L24)/HistoricalFS!L6),0) -> 0.24347496 | N13: =IFERROR(AVERAGE(C13:L13),0) -> 0.25130055 | O13: =IFERROR(MEDIAN(C13:L13),0) -> 0.25022868
B14: EBT Margin | C14: =IFERROR(HistoricalFS!C28,0) -> 0.2646761 | D14: =IFERROR(HistoricalFS!D28,0) -> 0.25678585 | E14: =IFERROR(HistoricalFS!E28,0) -> 0.24735183 | F14: =IFERROR(HistoricalFS!F28,0) -> 0.2543441 | G14: =IFERROR(HistoricalFS!G28,0) -> 0.23992507 | H14: =IFERROR(HistoricalFS!H28,0) -> 0.25487127 | I14: =IFERROR(HistoricalFS!I28,0) -> 0.24859455 | J14: =IFERROR(HistoricalFS!J28,0) -> 0.23710846 | ... L14: =IFERROR(HistoricalFS!L28,0) -> 0.24035735 | N14: =IFERROR(AVERAGE(C14:L14),0) -> 0.2486998 | O14: =IFERROR(MEDIAN(C14:L14),0) -> 0.24797319
B15: Net Profit Margin | C15: =IFERROR(HistoricalFS!C34,0) -> 0.19562616 | D15: =IFERROR(HistoricalFS!D34,0) -> 0.18764729 | E15: =IFERROR(HistoricalFS!E34,0) -> 0.18064401 | F15: =IFERROR(HistoricalFS!F34,0) -> 0.18606064 | G15: =IFERROR(HistoricalFS!G34,0) -> 0.17747803 | H15: =IFERROR(HistoricalFS!H34,0) -> 0.18666439 | I15: =IFERROR(HistoricalFS!I34,0) -> 0.17955818 | J15: =IFERROR(HistoricalFS!J34,0) -> 0.17233365 | ... L15: =IFERROR(HistoricalFS!L34,0) -> 0.17560041 | N15: =IFERROR(AVERAGE(C15:L15),0) -> 0.18186001 | O15: =IFERROR(MEDIAN(C15:L15),0) -> 0.1801011
B17: SalesExpenses%Sales | C17: =IFERROR(HistoricalFS!C16,0) -> 0.1845443 | D17: =IFERROR(HistoricalFS!D16,0) -> 0.1799332 | E17: =IFERROR(HistoricalFS!E16,0) -> 0.17458409 | F17: =IFERROR(HistoricalFS!F16,0) -> 0.18053024 | G17: =IFERROR(HistoricalFS!G16,0) -> 0.17192209 | H17: =IFERROR(HistoricalFS!H16,0) -> 0.14834599 | I17: =IFERROR(HistoricalFS!I16,0) -> 0.15634615 | J17: =IFERROR(HistoricalFS!J16,0) -> 0.16320556 | ... L17: =IFERROR(HistoricalFS!L16,0) -> 0.11938165 | N17: =IFERROR(AVERAGE(C17:L17),0) -> 0.16148039 | O17: =IFERROR(MEDIAN(C17:L17),0) -> 0.16756383
B18: Depreciation%Sales | C18: =IFERROR(HistoricalFS!C25,0) -> 0.017377538 | D18: =IFERROR(HistoricalFS!D25,0) -> 0.016843836 | E18: =IFERROR(HistoricalFS!E25,0) -> 0.016360151 | F18: =IFERROR(HistoricalFS!F25,0) -> 0.014037675 | G18: =IFERROR(HistoricalFS!G25,0) -> 0.022485011 | H18: =IFERROR(HistoricalFS!H25,0) -> 0.024759863 | I18: =IFERROR(HistoricalFS!I25,0) -> 0.024009929 | J18: =IFERROR(HistoricalFS!J25,0) -> 0.022274659 | ... L18: =IFERROR(HistoricalFS!L25,0) -> 0.020530777 | N18: =IFERROR(AVERAGE(C18:L18),0) -> 0.019937327 | O18: =IFERROR(MEDIAN(C18:L18),0) -> 0.020612306
B19: OperatingIncome%Sales | C19: =C13 -> 0.26497984 | D19: =D13 -> 0.25705712 | E19: =E13 -> 0.24777424 | F19: =F13 -> 0.25569598 | G19: =G13 -> 0.24581233 | H19: =H13 -> 0.25875123 | I19: =I13 -> 0.25268313 | J19: =J13 -> 0.24056365 | ... L19: =L13 -> 0.24347496 | N19: =IFERROR(AVERAGE(C19:L19),0) -> 0.25130055 | O19: =IFERROR(MEDIAN(C19:L19),0) -> 0.25022868
B21: Return on Capital Employed | C21: =IFERROR((HistoricalFS!C18-HistoricalFS!C24)/(SUM(HistoricalFS!C47:C48)+HistoricalFS!C49),0) -> 0.40367654 | D21: =IFERROR((HistoricalFS!D18-HistoricalFS!D24)/(SUM(HistoricalFS!D47:D48)+HistoricalFS!D49),0) -> 0.35055432 | E21: =IFERROR((HistoricalFS!E18-HistoricalFS!E24)/(SUM(HistoricalFS!E47:E48)+HistoricalFS!E49),0) -> 0.35727086 | F21: =IFERROR((HistoricalFS!F18-HistoricalFS!F24)/(SUM(HistoricalFS!F47:F48)+HistoricalFS!F49),0) -> 0.41839836 | G21: =IFERROR((HistoricalFS!G18-HistoricalFS!G24)/(SUM(HistoricalFS!G47:G48)+HistoricalFS!G49),0) -> 0.41798483 | H21: =IFERROR((HistoricalFS!H18-HistoricalFS!H24)/(SUM(HistoricalFS!H47:H48)+HistoricalFS!H49),0) -> 0.45083202 | I21: =IFERROR((HistoricalFS!I18-HistoricalFS!I24)/(SUM(HistoricalFS!I47:I48)+HistoricalFS!I49),0) -> 0.499737 | J21: =IFERROR((HistoricalFS!J18-HistoricalFS!J24)/(SUM(HistoricalFS!J47:J48)+HistoricalFS!J49),0) -> 0.552807 | ... L21: =IFERROR((HistoricalFS!L18-HistoricalFS!L24)/(SUM(HistoricalFS!L47:L48)+HistoricalFS!L49),0) -> 0.59689096 | N21: =IFERROR(AVERAGE(C21:L21),0) -> 0.46502329 | O21: =IFERROR(MEDIAN(C21:L21),0) -> 0.43461519
B22: Retained Earnings% | C22: =IFERROR(HistoricalFS!C44,0) -> 0.59680531 | D22: =IFERROR(HistoricalFS!D44,0) -> 0.58172208 | E22: =IFERROR(HistoricalFS!E44,0) -> 0.57055491 | F22: =IFERROR(HistoricalFS!F44,0) -> 0.58717111 | G22: =IFERROR(HistoricalFS!G44,0) -> 0.017232095 | H22: =IFERROR(HistoricalFS!H44,0) -> 0.54121256 | I22: =IFERROR(HistoricalFS!I44,0) -> 0.54291191 | J22: =IFERROR(HistoricalFS!J44,0) -> 0 | ... L22: =IFERROR(HistoricalFS!L44,0) -> 0 | N22: =IFERROR(AVERAGE(C22:L22),0) -> 0.38177906 | O22: =IFERROR(MEDIAN(C22:L22),0) -> 0.54206223
B23: Return on Equity% | C23: =IFERROR(HistoricalFS!C33/(SUM(HistoricalFS!C47:C48)),0) -> 0.29904885 | D23: =IFERROR(HistoricalFS!D33/(SUM(HistoricalFS!D47:D48)),0) -> 0.25675644 | E23: =IFERROR(HistoricalFS!E33/(SUM(HistoricalFS!E47:E48)),0) -> 0.26123015 | F23: =IFERROR(HistoricalFS!F33/(SUM(HistoricalFS!F47:F48)),0) -> 0.30466427 | G23: =IFERROR(HistoricalFS!G33/(SUM(HistoricalFS!G47:G48)),0) -> 0.33111048 | H23: =IFERROR(HistoricalFS!H33/(SUM(HistoricalFS!H47:H48)),0) -> 0.35456365 | I23: =IFERROR(HistoricalFS!I33/(SUM(HistoricalFS!I47:I48)),0) -> 0.38626191 | J23: =IFERROR(HistoricalFS!J33/(SUM(HistoricalFS!J47:J48)),0) -> 0.42968681 | ... L23: =IFERROR(HistoricalFS!L33/(SUM(HistoricalFS!L47:L48)),0) -> 0.47316265 | N23: =IFERROR(AVERAGE(C23:L23),0) -> 0.35676474 | O23: =IFERROR(MEDIAN(C23:L23),0) -> 0.34283706
B24: Self Sustained Growth Rate | C24: =IFERROR(C22*C23,0) -> 0.17847394 | D24: =IFERROR(D22*D23,0) -> 0.14936089 | E24: =IFERROR(E22*E23,0) -> 0.14904614 | F24: =IFERROR(F22*F23,0) -> 0.17889006 | G24: =IFERROR(G22*G23,0) -> 0.0057057271 | H24: =IFERROR(H22*H23,0) -> 0.1918943 | I24: =IFERROR(I22*I23,0) -> 0.20970619 | J24: =IFERROR(J22*J23,0) -> 0 | ... L24: =IFERROR(L22*L23,0) -> 0 | N24: =IFERROR(AVERAGE(C24:L24),0) -> 0.1242204 | O24: =IFERROR(MEDIAN(C24:L24),0) -> 0.16391742
B25: Interest Coverage Ratio | C25: =IFERROR((HistoricalFS!C18-HistoricalFS!C24)/HistoricalFS!C21,0) -> 872.39394 | D25: =IFERROR((HistoricalFS!D18-HistoricalFS!D24)/HistoricalFS!D21,0) -> 947.625 | E25: =IFERROR((HistoricalFS!E18-HistoricalFS!E24)/HistoricalFS!E21,0) -> 586.57692 | F25: =IFERROR((HistoricalFS!F18-HistoricalFS!F24)/HistoricalFS!F21,0) -> 189.14141 | G25: =IFERROR((HistoricalFS!G18-HistoricalFS!G24)/HistoricalFS!G21,0) -> 41.753247 | H25: =IFERROR((HistoricalFS!H18-HistoricalFS!H24)/HistoricalFS!H21,0) -> 66.689168 | I25: =IFERROR((HistoricalFS!I18-HistoricalFS!I24)/HistoricalFS!I21,0) -> 61.802296 | J25: =IFERROR((HistoricalFS!J18-HistoricalFS!J24)/HistoricalFS!J21,0) -> 69.623877 | ... L25: =IFERROR((HistoricalFS!L18-HistoricalFS!L24)/HistoricalFS!L21,0) -> 78.096734 | N25: =IFERROR(AVERAGE(C25:L25),0) -> 298.99378 | O25: =IFERROR(MEDIAN(C25:L25),0) -> 77.165976
B27: Debtor Turnover Ratio | C27: =IFERROR(HistoricalFS!C6/HistoricalFS!C59,0) -> 4.513189 | D27: =IFERROR(HistoricalFS!D6/HistoricalFS!D59,0) -> 5.2158111 | E27: =IFERROR(HistoricalFS!E6/HistoricalFS!E59,0) -> 4.9354127 | F27: =IFERROR(HistoricalFS!F6/HistoricalFS!F59,0) -> 5.3559204 | G27: =IFERROR(HistoricalFS!G6/HistoricalFS!G59,0) -> 5.1404756 | H27: =IFERROR(HistoricalFS!H6/HistoricalFS!H59,0) -> 5.4581934 | I27: =IFERROR(HistoricalFS!I6/HistoricalFS!I59,0) -> 4.5863191 | J27: =IFERROR(HistoricalFS!J6/HistoricalFS!J59,0) -> 4.5133122 | ... L27: =IFERROR(HistoricalFS!L6/HistoricalFS!L59,0) -> 4.324154 | N27: =IFERROR(AVERAGE(C27:L27),0) -> 4.8538989 | O27: =IFERROR(MEDIAN(C27:L27),0) -> 4.7608659
B28: Creditor Turnover Ratio | C28: =IFERROR(HistoricalFS!C6/HistoricalFS!C50,0) -> 6.4007305 | D28: =IFERROR(HistoricalFS!D6/HistoricalFS!D50,0) -> 7.4520531 | E28: =IFERROR(HistoricalFS!E6/HistoricalFS!E50,0) -> 6.2327983 | F28: =IFERROR(HistoricalFS!F6/HistoricalFS!F50,0) -> 6.0043045 | G28: =IFERROR(HistoricalFS!G6/HistoricalFS!G50,0) -> 5.6401696 | H28: =IFERROR(HistoricalFS!H6/HistoricalFS!H50,0) -> 4.5905659 | I28: =IFERROR(HistoricalFS!I6/HistoricalFS!I50,0) -> 4.3613164 | J28: =IFERROR(HistoricalFS!J6/HistoricalFS!J50,0) -> 5.0385054 | ... L28: =IFERROR(HistoricalFS!L6/HistoricalFS!L50,0) -> 4.6847581 | N28: =IFERROR(AVERAGE(C28:L28),0) -> 5.5534732 | O28: =IFERROR(MEDIAN(C28:L28),0) -> 5.3848499
B29: Inventory Turnover Ratio | C29: =IFERROR(HistoricalFS!C6/HistoricalFS!C60,0) -> 6790.375 | D29: =IFERROR(HistoricalFS!D6/HistoricalFS!D60,0) -> 5617.4286 | E29: =IFERROR(HistoricalFS!E6/HistoricalFS!E60,0) -> 4734.7692 | F29: =IFERROR(HistoricalFS!F6/HistoricalFS!F60,0) -> 14646.3 | G29: =IFERROR(HistoricalFS!G6/HistoricalFS!G60,0) -> 31389.8 | H29: =IFERROR(HistoricalFS!H6/HistoricalFS!H60,0) -> 20522.125 | I29: =IFERROR(HistoricalFS!I6/HistoricalFS!I60,0) -> 9587.7 | J29: =IFERROR(HistoricalFS!J6/HistoricalFS!J60,0) -> 8052.0714 | ... L29: =IFERROR(HistoricalFS!L6/HistoricalFS!L60,0) -> 12158.286 | N29: =IFERROR(AVERAGE(C29:L29),0) -> 12210.218 | O29: =IFERROR(MEDIAN(C29:L29),0) -> 9095.5107
B30: Fixed Asset Turnover | C30: =IFERROR(HistoricalFS!C6/HistoricalFS!C53,0) -> 9.2276202 | D30: =IFERROR(HistoricalFS!D6/HistoricalFS!D53,0) -> 10.081702 | E30: =IFERROR(HistoricalFS!E6/HistoricalFS!E53,0) -> 10.281801 | F30: =IFERROR(HistoricalFS!F6/HistoricalFS!F53,0) -> 11.91725 | G30: =IFERROR(HistoricalFS!G6/HistoricalFS!G53,0) -> 7.4994744 | H30: =IFERROR(HistoricalFS!H6/HistoricalFS!H53,0) -> 7.8101422 | I30: =IFERROR(HistoricalFS!I6/HistoricalFS!I53,0) -> 9.0033806 | J30: =IFERROR(HistoricalFS!J6/HistoricalFS!J53,0) -> 10.98991 | ... L30: =IFERROR(HistoricalFS!L6/HistoricalFS!L53,0) -> 11.075522 | N30: =IFERROR(AVERAGE(C30:L30),0) -> 10.017475 | O30: =IFERROR(MEDIAN(C30:L30),0) -> 10.181752
B31: Capital Turnover Ratio | C31: =IFERROR(HistoricalFS!C6/(SUM(HistoricalFS!C47:C48)),0) -> 1.5286751 | D31: =IFERROR(HistoricalFS!D6/(SUM(HistoricalFS!D47:D48)),0) -> 1.3682929 | E31: =IFERROR(HistoricalFS!E6/(SUM(HistoricalFS!E47:E48)),0) -> 1.4461047 | F31: =IFERROR(HistoricalFS!F6/(SUM(HistoricalFS!F47:F48)),0) -> 1.6374461 | G31: =IFERROR(HistoricalFS!G6/(SUM(HistoricalFS!G47:G48)),0) -> 1.865642 | H31: =IFERROR(HistoricalFS!H6/(SUM(HistoricalFS!H47:H48)),0) -> 1.8994713 | I31: =IFERROR(HistoricalFS!I6/(SUM(HistoricalFS!I47:I48)),0) -> 2.1511796 | J31: =IFERROR(HistoricalFS!J6/(SUM(HistoricalFS!J47:J48)),0) -> 2.4933425 | ... L31: =IFERROR(HistoricalFS!L6/(SUM(HistoricalFS!L47:L48)),0) -> 2.6945418 | N31: =IFERROR(AVERAGE(C31:L31),0) -> 1.9746821 | O31: =IFERROR(MEDIAN(C31:L31),0) -> 1.8825566
B33: (in days)
B34: Debtor Days | C34: =IFERROR(365/C27,0) -> 80.874077 | D34: =IFERROR(365/D27,0) -> 69.979528 | E34: =IFERROR(365/E27,0) -> 73.955314 | F34: =IFERROR(365/F27,0) -> 68.148884 | G34: =IFERROR(365/G27,0) -> 71.005104 | H34: =IFERROR(365/H27,0) -> 66.871943 | I34: =IFERROR(365/I27,0) -> 79.58452 | J34: =IFERROR(365/J27,0) -> 80.87187 | ... L34: =IFERROR(365/L27,0) -> 84.409574 | N34: =IFERROR(AVERAGE(C34:L34),0) -> 75.688044 | O34: =IFERROR(MEDIAN(C34:L34),0) -> 76.769917
B35: Payable Days | C35: =IFERROR(365/C28,0) -> 57.024741 | D35: =IFERROR(365/D28,0) -> 48.979791 | E35: =IFERROR(365/E28,0) -> 58.561176 | F35: =IFERROR(365/F28,0) -> 60.789722 | G35: =IFERROR(365/G28,0) -> 64.714366 | H35: =IFERROR(365/H28,0) -> 79.510894 | I35: =IFERROR(365/I28,0) -> 83.690327 | J35: =IFERROR(365/J28,0) -> 72.442118 | ... L35: =IFERROR(365/L28,0) -> 77.912241 | N35: =IFERROR(AVERAGE(C35:L35),0) -> 67.478199 | O35: =IFERROR(MEDIAN(C35:L35),0) -> 67.935489
B36: Inventory Days | C36: =IFERROR(365/C29,0) -> 0.053752554 | D36: =IFERROR(365/D29,0) -> 0.064976349 | E36: =IFERROR(365/E29,0) -> 0.07708929 | F36: =IFERROR(365/F29,0) -> 0.02492097 | G36: =IFERROR(365/G29,0) -> 0.011627981 | H36: =IFERROR(365/H29,0) -> 0.017785683 | I36: =IFERROR(365/I29,0) -> 0.03806961 | J36: =IFERROR(365/J29,0) -> 0.045329951 | ... L36: =IFERROR(365/L29,0) -> 0.03002068 | N36: =IFERROR(AVERAGE(C36:L36),0) -> 0.040599854 | O36: =IFERROR(MEDIAN(C36:L36),0) -> 0.040247543
B37: Cash Conversion Cycle | C37: =SUM(C34,C36)-C35 -> 23.903089 | D37: =SUM(D34,D36)-D35 -> 21.064714 | E37: =SUM(E34,E36)-E35 -> 15.471228 | F37: =SUM(F34,F36)-F35 -> 7.3840834 | G37: =SUM(G34,G36)-G35 -> 6.3023657 | H37: =SUM(H34,H36)-H35 -> -12.621165 | I37: =SUM(I34,I36)-I35 -> -4.0677378 | J37: =SUM(J34,J36)-J35 -> 8.4750818 | ... L37: =SUM(L34,L36)-L35 -> 6.5273535 | N37: =IFERROR(AVERAGE(C37:L37),0) -> 8.2504456 | O37: =IFERROR(MEDIAN(C37:L37),0) -> 7.9295826
B39: CFO/Sales | C39: =IFERROR(HistoricalFS!C78/HistoricalFS!C6,0) -> 0.17616847 | D39: =IFERROR(HistoricalFS!D78/HistoricalFS!D6,0) -> 0.20440635 | E39: =IFERROR(HistoricalFS!E78/HistoricalFS!E6,0) -> 0.21966792 | F39: =IFERROR(HistoricalFS!F78/HistoricalFS!F6,0) -> 0.18977489 | G39: =IFERROR(HistoricalFS!G78/HistoricalFS!G6,0) -> 0.19462373 | H39: =IFERROR(HistoricalFS!H78/HistoricalFS!H6,0) -> 0.23573339 | I39: =IFERROR(HistoricalFS!I78/HistoricalFS!I6,0) -> 0.21981289 | J39: =IFERROR(HistoricalFS!J78/HistoricalFS!J6,0) -> 0.19251036 | ... L39: =IFERROR(HistoricalFS!L78/HistoricalFS!L6,0) -> 0.1842835 | N39: =IFERROR(AVERAGE(C39:L39),0) -> 0.19889251 | O39: =IFERROR(MEDIAN(C39:L39),0) -> 0.19356704
B40: CFO/Total Assets | C40: =IFERROR(HistoricalFS!C78/HistoricalFS!C64,0) -> 0.21678314 | D40: =IFERROR(HistoricalFS!D78/HistoricalFS!D64,0) -> 0.23563269 | E40: =IFERROR(HistoricalFS!E78/HistoricalFS!E64,0) -> 0.25723418 | F40: =IFERROR(HistoricalFS!F78/HistoricalFS!F64,0) -> 0.24402771 | G40: =IFERROR(HistoricalFS!G78/HistoricalFS!G64,0) -> 0.25428089 | H40: =IFERROR(HistoricalFS!H78/HistoricalFS!H64,0) -> 0.29772601 | I40: =IFERROR(HistoricalFS!I78/HistoricalFS!I64,0) -> 0.29909739 | J40: =IFERROR(HistoricalFS!J78/HistoricalFS!J64,0) -> 0.30381705 | ... L40: =IFERROR(HistoricalFS!L78/HistoricalFS!L64,0) -> 0.29657924 | N40: =IFERROR(AVERAGE(C40:L40),0) -> 0.26899066 | O40: =IFERROR(MEDIAN(C40:L40),0) -> 0.27098125
B41: CFO/Total Debt | C41: =IFERROR(HistoricalFS!C78/HistoricalFS!C49,0) -> 78.122449 | D41: =IFERROR(HistoricalFS!D78/HistoricalFS!D49,0) -> 83.435986 | E41: =IFERROR(HistoricalFS!E78/HistoricalFS!E49,0) -> 109.48178 | F41: =IFERROR(HistoricalFS!F78/HistoricalFS!F49,0) -> 448.30645 | G41: =IFERROR(HistoricalFS!G78/HistoricalFS!G49,0) -> 3.7369709 | H41: =IFERROR(HistoricalFS!H78/HistoricalFS!H49,0) -> 4.9649775 | I41: =IFERROR(HistoricalFS!I78/HistoricalFS!I49,0) -> 5.3914045 | J41: =IFERROR(HistoricalFS!J78/HistoricalFS!J49,0) -> 5.6455515 | ... L41: =IFERROR(HistoricalFS!L78/HistoricalFS!L49,0) -> 5.0097956 | N41: =IFERROR(AVERAGE(C41:L41),0) -> 74.925931 | O41: =IFERROR(MEDIAN(C41:L41),0) -> 5.518478

Sheet  Forecasting
B3: ='Data Sheet'!B1&" - " & 'Data Sheet'!A17&" Forecasting" -> TATA CONSULTANCY SERVICES LTD - Sales Forecasting | G3: ='Data Sheet'!B1&" - "&"EBITDA Forecasting" -> TATA CONSULTANCY SERVICES LTD - EBITDA Forecasting | L3: ='Data Sheet'!B1&" - "&"EPS Forecasting" -> TATA CONSULTANCY SERVICES LTD - EPS Forecasting
C4: Year | D4: Sales | E4: Sales Growth | H4: Year | I4: EBITDA | J4: EBITDA Growth | M4: Year | N4: EPS | O4: EPS Growth
B5: 1 | C5: ='Data Sheet'!$B$16 -> 42460 | D5: {=TRANSPOSE('Data Sheet'!B17:K17)} -> 108646 | G5: 1 | H5: ='Data Sheet'!$B$16 -> 42460 | I5: {=TRANSPOSE(HistoricalFS!C18:M18)} -> 30677 | L5: 1 | M5: ='Data Sheet'!$B$16 -> 42460 | N5: {=TRANSPOSE(HistoricalFS!C38:L38)} -> 53.931843
B6: =B5+1 -> 2 | C6: =C5+365 -> 42825 | D6: 117966 | E6: =D6/D5-1 -> 0.085783186 | G6: =G5+1 -> 2 | H6: =H5+365 -> 42825 | I6: 32311 | J6: =I6/I5-1 -> 0.053264661 | L6: =L5+1 -> 2 | M6: =M5+365 -> 42825 | N6: 56.16991 | O6: =N6/N5-1 -> 0.041498071
B7: =B6+1 -> 3 | C7: =C6+365 -> 43190 | D7: 123104 | E7: =D7/D6-1 -> 0.043554923 | G7: =G6+1 -> 3 | H7: =H6+365 -> 43190 | I7: 32516 | J7: =I7/I6-1 -> 0.0063445885 | L7: =L6+1 -> 3 | M7: =M6+365 -> 43190 | N7: 58.083895 | O7: =N7/N6-1 -> 0.034074907
B8: =B7+1 -> 4 | C8: =C7+365 -> 43555 | D8: 146463 | E8: =D8/D7-1 -> 0.18975013 | G8: =G7+1 -> 4 | H8: =H7+365 -> 43555 | I8: 39506 | J8: =I8/I7-1 -> 0.21497109 | L8: =L7+1 -> 4 | M8: =M7+365 -> 43555 | N8: 72.622855 | O8: =N8/N7-1 -> 0.25030966
B9: =B8+1 -> 5 | C9: =C8+365 -> 43920 | D9: 156949 | E9: =D9/D8-1 -> 0.071594874 | G9: =G8+1 -> 5 | H9: =H8+365 -> 43920 | I9: 42109 | J9: =I9/I8-1 -> 0.065888726 | L9: =L8+1 -> 5 | M9: =M8+365 -> 43920 | N9: 74.232491 | O9: =N9/N8-1 -> 0.022164324
B10: =B9+1 -> 6 | C10: =C9+365 -> 44285 | D10: 164177 | E10: =D10/D9-1 -> 0.046053177 | G10: =G9+1 -> 6 | H10: =H9+365 -> 44285 | I10: 46546 | J10: =I10/I9-1 -> 0.1053694 | L10: =L9+1 -> 6 | M10: =M9+365 -> 44285 | N10: 82.847179 | O10: =N10/N9-1 -> 0.1160501
B11: =B10+1 -> 7 | C11: =C10+365 -> 44650 | D11: 191754 | E11: =D11/D10-1 -> 0.16797115 | G11: =G10+1 -> 7 | H11: =H10+365 -> 44650 | I11: 53057 | J11: =I11/I10-1 -> 0.13988313 | L11: =L10+1 -> 7 | M11: =M10+365 -> 44650 | N11: 94.096909 | O11: =N11/N10-1 -> 0.13578893
B12: =B11+1 -> 8 | C12: =C11+365 -> 45015 | D12: 225458 | E12: =D12/D11-1 -> 0.17576687 | G12: =G11+1 -> 8 | H12: =H11+365 -> 45015 | I12: 59259 | J12: =I12/I11-1 -> 0.11689315 | L12: =L11+1 -> 8 | M12: =M11+365 -> 45015 | N12: 106.18458 | O12: =N12/N11-1 -> 0.12845982
B13: =B12+1 -> 9 | C13: =C12+365 -> 45380 | D13: 240893 | E13: =D13/D12-1 -> 0.068460645 | G13: =G12+1 -> 9 | H13: =H12+365 -> 45380 | I13: 64296 | J13: =I13/I12-1 -> 0.084999747 | L13: =L12+1 -> 9 | M13: =M12+365 -> 45380 | N13: 117.83809 | O13: =N13/N12-1 -> 0.10974768
B14: =B13+1 -> 10 | C14: =C13+365 -> 45745 | D14: 255324 | E14: =D14/D13-1 -> 0.059906265 | G14: =G13+1 -> 10 | H14: =H13+365 -> 45745 | I14: 67407 | J14: =I14/I13-1 -> 0.048385592 | L14: =L13+1 -> 10 | M14: =M13+365 -> 45745 | N14: 123.91863 | O14: =N14/N13-1 -> 0.051600797
B15: =B14+1 -> 11 | C15: =C14+365 -> 46110 | D15: =FORECAST(B15,$D$5:$D$14,$B$5:$B$14) -> 267588.8 | E15: =D15/D14-1 -> 0.048036221 | G15: =G14+1 -> 11 | H15: =H14+365 -> 46110 | I15: =FORECAST(G15,$I$5:$I$14,$G$5:$G$14) -> 71210.733 | J15: =I15/I14-1 -> 0.056429352 | L15: =L14+1 -> 11 | M15: =M14+365 -> 46110 | N15: =FORECAST(L15,$N$5:$N$14,$L$5:$L$14) -> 129.82926 | O15: =N15/N14-1 -> 0.047697661
B16: =B15+1 -> 12 | C16: =C15+365 -> 46475 | D16: =FORECAST(B16,$D$5:$D$14,$B$5:$B$14) -> 284773.42 | E16: =D16/D15-1 -> 0.064220245 | G16: =G15+1 -> 12 | H16: =H15+365 -> 46475 | I16: =FORECAST(G16,$I$5:$I$14,$G$5:$G$14) -> 75654.794 | J16: =I16/I15-1 -> 0.062407174 | L16: =L15+1 -> 12 | M16: =M15+365 -> 46475 | N16: =FORECAST(L16,$N$5:$N$14,$L$5:$L$14) -> 138.16319 | O16: =N16/N15-1 -> 0.064191471
B17: =B16+1 -> 13 | C17: =C16+365 -> 46840 | D17: =FORECAST(B17,$D$5:$D$14,$B$5:$B$14) -> 301958.04 | E17: =D17/D16-1 -> 0.060344882 | G17: =G16+1 -> 13 | H17: =H16+365 -> 46840 | I17: =FORECAST(G17,$I$5:$I$14,$G$5:$G$14) -> 80098.855 | J17: =I17/I16-1 -> 0.058741295 | L17: =L16+1 -> 13 | M17: =M16+365 -> 46840 | N17: =FORECAST(L17,$N$5:$N$14,$L$5:$L$14) -> 146.49712 | O17: =N17/N16-1 -> 0.060319475
B18: =B17+1 -> 14 | C18: =C17+365 -> 47205 | D18: =FORECAST(B18,$D$5:$D$14,$B$5:$B$14) -> 319142.65 | E18: =D18/D17-1 -> 0.056910617 | G18: =G17+1 -> 14 | H18: =H17+365 -> 47205 | I18: =FORECAST(G18,$I$5:$I$14,$G$5:$G$14) -> 84542.915 | J18: =I18/I17-1 -> 0.055482199 | L18: =L17+1 -> 14 | M18: =M17+365 -> 47205 | N18: =FORECAST(L18,$N$5:$N$14,$L$5:$L$14) -> 154.83105 | O18: =N18/N17-1 -> 0.05688802
B19: =B18+1 -> 15 | C19: =C18+365 -> 47570 | D19: =FORECAST(B19,$D$5:$D$14,$B$5:$B$14) -> 336327.27 | E19: =D19/D18-1 -> 0.053846197 | G19: =G18+1 -> 15 | H19: =H18+365 -> 47570 | I19: =FORECAST(G19,$I$5:$I$14,$G$5:$G$14) -> 88986.976 | J19: =I19/I18-1 -> 0.052565737 | L19: =L18+1 -> 15 | M19: =M18+365 -> 47570 | N19: =FORECAST(L19,$N$5:$N$14,$L$5:$L$14) -> 163.16498 | O19: =N19/N18-1 -> 0.053825967

Sheet WACC
B2: Weighted Average Cost of Capital
B4: All figures are in INR unless stated otherwise
B6: Peer Companies
G8: Debt/ | H8: Debt/ | I8: Levered | J8: Unlevered
B9: Name of the Companies | D9: Country | E9: Total Debt | F9: Total Equity | G9: Tax Rate 1 | H9: Equity | I9: Capital | J9: Beta 2 | K9: Beta 3
B11: TCS | D11: India | E11: 10932 | F11: 106415 | G11: 0.3 | H11: =E11/F11 -> 0.10272988 | I11: =E11/(F11+E11) -> 0.093159604 | J11: 1 | K11: =J11/(1+(1-G11)*H11) -> 0.93291335
B12: Infosys | D12: India | E12: 8755 | F12: 103330 | G12: 0.3 | H12: =E12/F12 -> 0.08472854 | I12: =E12/(F12+E12) -> 0.078110363 | J12: 1 | K12: =J12/(1+(1-G12)*H12) -> 0.94401074
B13: Wipro | D13: India | E13: 16164 | F13: 85586 | G13: 0.3 | H13: =E13/F13 -> 0.18886266 | I13: =E13/(F13+E13) -> 0.15885995 | J13: 1 | K13: =J13/(1+(1-G13)*H13) -> 0.88323316
B14: HCL Tech | D14: India | E14: 6780 | F14: 71249 | G14: 0.3 | H14: =E14/F14 -> 0.09515923 | I14: =E14/(F14+E14) -> 0.086890771 | J14: 1 | K14: =J14/(1+(1-G14)*H14) -> 0.93754852
B15: LT Mindtree | D15: India | E15: 2383 | F15: 23404 | G15: 0.3 | H15: =E15/F15 -> 0.1018202 | I15: =E15/(F15+E15) -> 0.092410905 | J15: 1 | K15: =J15/(1+(1-G15)*H15) -> 0.93346788
F17: Average | G17: =AVERAGE(G11:G15) -> 0.3 | H17: =AVERAGE(H11:H15) -> 0.1146601 | I17: =AVERAGE(I11:I15) -> 0.10188632 | J17: =AVERAGE(J11:J15) -> 1 | K17: =AVERAGE(K11:K15) -> 0.92623473
F18: Median | G18: =MEDIAN(G11:G15) -> 0.3 | H18: =MEDIAN(H11:H15) -> 0.1018202 | I18: =MEDIAN(I11:I15) -> 0.092410905 | J18: =MEDIAN(J11:J15) -> 1 | K18: =MEDIAN(K11:K15) -> 0.93346788
B22: Cost of Debt | G22: Cost o Equity
B24: pre-tax cost of debt | C24: 0.084 | G24: Risk Free Rate | K24: 0.065
B25: Tax Rate | C25: 0.3 | G25: Equity Risk Premium | K25: 0.08
B26: Post Tax Cost of Debt | C26: =C24*(1-C25) -> 0.0588 | G26: Levered Beta 4 | K26: =K36 -> 1.416436
G27: Cost of Equity | K27: =K24+K26*K25 -> 0.17831488
B31: Capital Structre | G31: Levered Beta
D33: Current | E33: Target | G33: Companies Median Unlevered Beta | K33: =K18 -> 0.93346788
B34: Total Debt | C34: 17440 | D34: =C34/$C$36 -> 0.35087013 | E34: 0.425 | G34: Target Debt/Equity | K34: =E38 -> 0.73913043
B35: Market Capitalization | C35: 32265 | D35: =C35/$C$36 -> 0.64912987 | E35: =E36-E34 -> 0.575 | G35: Tax Rate | K35: =C25 -> 0.3
B36: Total Capital | C36: =SUM(C34:C35) -> 49705 | D36: =C36/$C$36 -> 1 | E36: =D36 -> 1 | G36: Levered Beta | K36: =K33*(1+(1-K35)*K34) -> 1.416436
B38: Debt/Equity | D38: =D34/D35 -> 0.54052379 | E38: =E34/E35 -> 0.73913043
G39: Weighted Average Cost of Capital
B40: Notes: | J40: Total Cost | K40: Total Weight
B41: 1. Tax Rate considered as Marginal tax rate for the country
B42: 2. Levered Beta is based on 5year monthly data | G42: Debt | J42: =C26 -> 0.0588 | K42: =E34 -> 0.425
B43: 3. Unlevered Beta =Levered Beta/(1+(1-Tax Rate)*Debt/Equity) | G43: Equity | J43: =K27 -> 0.17831488 | K43: =E35 -> 0.575
B44: 4. Levered Beta= Unlevered Beta*(1+(1-Tax Rate)*Debt/Equity) | G44: WACC | K44: =SUMPRODUCT( J42:J43,K42:K43) -> 0.12752106

Sheet Data Sheet
A1: COMPANY NAME | B1: TATA CONSULTANCY SERVICES LTD | E1: =IF(B2<>B3, "A NEW VERSION OF THE WORKSHEET IS AVAILABLE", "")
A2: LATEST VERSION | B2: 2.1 | E2: PLEASE DO NOT MAKE ANY CHANGES TO THIS SHEET
A3: CURRENT VERSION | B3: 2.1
A5: META
A6: Number of shares | B6: =IF(B9>0, B9/B8, 0) -> 361.84904
A7: Face Value | B7: 1
A8: Current Price | B8: 2686.65
A9: Market Capitalization | B9: 972161.71
A15: PROFIT & LOSS
A16: Report Date | B16: 42460 | C16: 42825 | D16: 43190 | E16: 43555 | F16: 43921 | G16: 44286 | H16: 44651 | I16: 45016 | J16: 45382 | K16: 45747
A17: Sales | B17: 108646 | C17: 117966 | D17: 123104 | E17: 146463 | F17: 156949 | G17: 164177 | H17: 191754 | I17: 225458 | J17: 240893 | K17: 255324
A18: Raw Material Cost | C18: 94 | D18: 86 | E18: 40 | F18: 18 | G18: 14 | H18: 29 | I18: 37 | J18: 42 | K18: 49
A19: Change in Inventory | C19: 1
A20: Power and Fuel
A21: Other Mfr. Exp | B21: 2571 | C21: 2715 | D21: 2614 | E21: 2230 | F21: 1887 | G21: 1448 | H21: 1134 | I21: 1844 | J21: 3660 | K21: 11599
A22: Employee Cost | B22: 55348 | C22: 61621 | D22: 66396 | E22: 78246 | F22: 85952 | G22: 91814 | H22: 107554 | I22: 127522 | J22: 140131 | K22: 145788
A23: Selling and admin | B23: 15589 | C23: 16392 | D23: 16808 | E23: 20387 | F23: 20527 | G23: 18322 | H23: 23187 | I23: 28913 | J23: 24151 | K23: 20729
A24: Other Expenses | B24: 4461 | C24: 4834 | D24: 4684 | E24: 6054 | F24: 6456 | G24: 6033 | H24: 6793 | I24: 7883 | J24: 8613 | K24: 9752
A25: Other Income | B25: 3084 | C25: 4221 | D25: 3642 | E25: 4311 | F25: 4592 | G25: 1916 | H25: 4018 | I25: 3449 | J25: 3464 | K25: 3962
A26: Depreciation | B26: 1888 | C26: 1987 | D26: 2014 | E26: 2056 | F26: 3529 | G26: 4065 | H26: 4604 | I26: 5022 | J26: 4985 | K26: 5242
A27: Interest | B27: 33 | C27: 32 | D27: 52 | E27: 198 | F27: 924 | G27: 637 | H27: 784 | I27: 779 | J27: 778 | K27: 796
A28: Profit before tax | B28: 31840 | C28: 34513 | D28: 34092 | E28: 41563 | F28: 42248 | G28: 43760 | H28: 51687 | I28: 56907 | J28: 61997 | K28: 65331
A29: Tax | B29: 7502 | C29: 8156 | D29: 8212 | E29: 10001 | F29: 9801 | G29: 11198 | H29: 13238 | I29: 14604 | J29: 15898 | K29: 16534
A30: Net profit | B30: 24270 | C30: 26289 | D30: 25826 | E30: 31472 | F30: 32340 | G30: 32430 | H30: 38327 | I30: 42147 | J30: 45908 | K30: 48553
A31: Dividend Amount | B31: 8569.5 | C31: 9259 | D31: 9550 | E31: 11250 | F31: 27375 | G31: 14060 | H31: 15738 | I31: 42090 | J31: 26426 | K31: 45612
A32: EBITDA | B32: =B30+B29+B27+B26 -> 33693 | C32: =C30+C29+C27+C26 -> 36464 | D32: =D30+D29+D27+D26 -> 36104 | E32: =E30+E29+E27+E26 -> 43727 | F32: =F30+F29+F27+F26 -> 46594 | G32: =G30+G29+G27+G26 -> 48330 | H32: =H30+H29+H27+H26 -> 56953 | I32: =I30+I29+I27+I26 -> 62552 | ... K32: =K30+K29+K27+K26 -> 71125
A39: Quarters
A40: Report Date | B40: 45199 | C40: 45291 | D40: 45382 | E40: 45473 | F40: 45565 | G40: 45657 | H40: 45747 | I40: 45838 | J40: 45930 | K40: 46022
A41: Sales | B41: 59692 | C41: 60583 | D41: 61237 | E41: 62613 | F41: 64259 | G41: 63973 | H41: 64479 | I41: 63437 | J41: 65799 | K41: 67087
A42: Expenses | B42: 43946 | C42: 44195 | D42: 44073 | E42: 45951 | F42: 47528 | G42: 46939 | H42: 47499 | I42: 46562 | J42: 47821 | K42: 48818
A43: Other Income | B43: 1006 | C43: -96 | D43: 1157 | E43: 962 | F43: 729 | G43: 1243 | H43: 1028 | I43: 1660 | J43: -268 | K43: -2273
A44: Depreciation | B44: 1263 | C44: 1233 | D44: 1246 | E44: 1220 | F44: 1266 | G44: 1377 | H44: 1379 | I44: 1361 | J44: 1413 | K44: 1380
A45: Interest | B45: 159 | C45: 230 | D45: 226 | E45: 173 | F45: 162 | G45: 234 | H45: 227 | I45: 195 | J45: 229 | K45: 538
A46: Profit before tax | B46: 15330 | C46: 14829 | D46: 16849 | E46: 16231 | F46: 16032 | G46: 16666 | H46: 16402 | I46: 16979 | J46: 16068 | K46: 14078
A47: Tax | B47: 3950 | C47: 3732 | D47: 4347 | E47: 4126 | F47: 4077 | G47: 4222 | H47: 4109 | I47: 4160 | J47: 3937 | K47: 3358
A48: Net profit | B48: 11342 | C48: 11058 | D48: 12434 | E48: 12040 | F48: 11909 | G48: 12380 | H48: 12224 | I48: 12760 | J48: 12075 | K48: 10657
A49: Operating Profit | B49: 15746 | C49: 16388 | D49: 17164 | E49: 16662 | F49: 16731 | G49: 17034 | H49: 16980 | I49: 16875 | J49: 17978 | K49: 18269
A54: BALANCE SHEET
A55: Report Date | B55: 42460 | C55: 42825 | D55: 43190 | E55: 43555 | F55: 43921 | G55: 44286 | H55: 44651 | I55: 45016 | J55: 45382 | K55: 45747
A56: Equity Share Capital | B56: 197 | C56: 197 | D56: 191 | E56: 375 | F56: 375 | G56: 370 | H56: 366 | I56: 366 | J56: 362 | K56: 362
...

Sheet Common Size Statement
B2: ="Common Size Income Statement -"&'Data Sheet'!B1 -> Common Size Income Statement -TATA CONSULTANCY SERVICES LTD
B4: Particulars | C4: ='Data Sheet'!B16 -> 42460 | D4: ='Data Sheet'!C16 -> 42825 | E4: ='Data Sheet'!D16 -> 43190 | F4: ='Data Sheet'!E16 -> 43555 | G4: ='Data Sheet'!F16 -> 43921 | H4: ='Data Sheet'!G16 -> 44286 | I4: ='Data Sheet'!H16 -> 44651 | J4: ='Data Sheet'!I16 -> 45016 | ... L4: ='Data Sheet'!K16 -> 45747
B6: ='Data Sheet'!A17 -> Sales | C6: ='Data Sheet'!B17/'Data Sheet'!B$17 -> 1 | D6: ='Data Sheet'!C17/'Data Sheet'!C$17 -> 1 | E6: ='Data Sheet'!D17/'Data Sheet'!D$17 -> 1 | F6: ='Data Sheet'!E17/'Data Sheet'!E$17 -> 1 | G6: ='Data Sheet'!F17/'Data Sheet'!F$17 -> 1 | H6: ='Data Sheet'!G17/'Data Sheet'!G$17 -> 1 | I6: ='Data Sheet'!H17/'Data Sheet'!H$17 -> 1 | J6: ='Data Sheet'!I17/'Data Sheet'!I$17 -> 1 | ... L6: ='Data Sheet'!K17/'Data Sheet'!K$17 -> 1
B7: ='Data Sheet'!A18 -> Raw Material Cost | C7: ='Data Sheet'!B18/'Data Sheet'!B$17 -> 0 | D7: ='Data Sheet'!C18/'Data Sheet'!C$17 -> 0.00079683977 | E7: ='Data Sheet'!D18/'Data Sheet'!D$17 -> 0.00069859631 | F7: ='Data Sheet'!E18/'Data Sheet'!E$17 -> 0.00027310652 | G7: ='Data Sheet'!F18/'Data Sheet'!F$17 -> 0.00011468694 | H7: ='Data Sheet'!G18/'Data Sheet'!G$17 -> 8.527382e-05 | I7: ='Data Sheet'!H18/'Data Sheet'!H$17 -> 0.00015123544 | J7: ='Data Sheet'!I18/'Data Sheet'!I$17 -> 0.00016411039 | ... L7: ='Data Sheet'!K18/'Data Sheet'!K$17 -> 0.00019191302
B8: ='Data Sheet'!A19 -> Change in Inventory | C8: ='Data Sheet'!B19/'Data Sheet'!B$17 -> 0 | D8: ='Data Sheet'!C19/'Data Sheet'!C$17 -> 8.4770188e-06 | E8: ='Data Sheet'!D19/'Data Sheet'!D$17 -> 0 | F8: ='Data Sheet'!E19/'Data Sheet'!E$17 -> 0 | G8: ='Data Sheet'!F19/'Data Sheet'!F$17 -> 0 | H8: ='Data Sheet'!G19/'Data Sheet'!G$17 -> 0 | I8: ='Data Sheet'!H19/'Data Sheet'!H$17 -> 0 | J8: ='Data Sheet'!I19/'Data Sheet'!I$17 -> 0 | ... L8: ='Data Sheet'!K19/'Data Sheet'!K$17 -> 0
B9: ='Data Sheet'!A20 -> Power and Fuel | C9: ='Data Sheet'!B20/'Data Sheet'!B$17 -> 0 | D9: ='Data Sheet'!C20/'Data Sheet'!C$17 -> 0 | E9: ='Data Sheet'!D20/'Data Sheet'!D$17 -> 0 | F9: ='Data Sheet'!E20/'Data Sheet'!E$17 -> 0 | G9: ='Data Sheet'!F20/'Data Sheet'!F$17 -> 0 | H9: ='Data Sheet'!G20/'Data Sheet'!G$17 -> 0 | I9: ='Data Sheet'!H20/'Data Sheet'!H$17 -> 0 | J9: ='Data Sheet'!I20/'Data Sheet'!I$17 -> 0 | ... L9: ='Data Sheet'!K20/'Data Sheet'!K$17 -> 0
B10: ='Data Sheet'!A21 -> Other Mfr. Exp | C10: ='Data Sheet'!B21/'Data Sheet'!B$17 -> 0.02366401 | D10: ='Data Sheet'!C21/'Data Sheet'!C$17 -> 0.023015106 | E10: ='Data Sheet'!D21/'Data Sheet'!D$17 -> 0.021234079 | F10: ='Data Sheet'!E21/'Data Sheet'!E$17 -> 0.015225688 | G10: ='Data Sheet'!F21/'Data Sheet'!F$17 -> 0.012023014 | H10: ='Data Sheet'!G21/'Data Sheet'!G$17 -> 0.0088197494 | I10: ='Data Sheet'!H21/'Data Sheet'!H$17 -> 0.0059138271 | J10: ='Data Sheet'!I21/'Data Sheet'!I$17 -> 0.0081789069 | ... L10: ='Data Sheet'!K21/'Data Sheet'!K$17 -> 0.045428554
B11: ='Data Sheet'!A22 -> Employee Cost | C11: ='Data Sheet'!B22/'Data Sheet'!B$17 -> 0.50943431 | D11: ='Data Sheet'!C22/'Data Sheet'!C$17 -> 0.52236238 | E11: ='Data Sheet'!D22/'Data Sheet'!D$17 -> 0.53934884 | F11: ='Data Sheet'!E22/'Data Sheet'!E$17 -> 0.53423732 | G11: ='Data Sheet'!F22/'Data Sheet'!F$17 -> 0.54764286 | H11: ='Data Sheet'!G22/'Data Sheet'!G$17 -> 0.5592379 | I11: ='Data Sheet'!H22/'Data Sheet'!H$17 -> 0.56089573 | J11: ='Data Sheet'!I22/'Data Sheet'!I$17 -> 0.56561311 | ... L11: ='Data Sheet'!K22/'Data Sheet'!K$17 -> 0.57099215
B12: ='Data Sheet'!A23 -> Selling and admin | C12: ='Data Sheet'!B23/'Data Sheet'!B$17 -> 0.14348434 | D12: ='Data Sheet'!C23/'Data Sheet'!C$17 -> 0.13895529 | E12: ='Data Sheet'!D23/'Data Sheet'!D$17 -> 0.13653496 | F12: ='Data Sheet'!E23/'Data Sheet'!E$17 -> 0.13919556 | G12: ='Data Sheet'!F23/'Data Sheet'!F$17 -> 0.13078771 | H12: ='Data Sheet'!G23/'Data Sheet'!G$17 -> 0.11159907 | I12: ='Data Sheet'!H23/'Data Sheet'!H$17 -> 0.12092055 | J12: ='Data Sheet'!I23/'Data Sheet'!I$17 -> 0.12824118 | ... L12: ='Data Sheet'!K23/'Data Sheet'!K$17 -> 0.081187041
B13: ='Data Sheet'!A24 -> Other Expenses | C13: ='Data Sheet'!B24/'Data Sheet'!B$17 -> 0.041059956 | D13: ='Data Sheet'!C24/'Data Sheet'!C$17 -> 0.040977909 | E13: ='Data Sheet'!D24/'Data Sheet'!D$17 -> 0.038049129 | F13: ='Data Sheet'!E24/'Data Sheet'!E$17 -> 0.041334672 | G13: ='Data Sheet'!F24/'Data Sheet'!F$17 -> 0.041134381 | H13: ='Data Sheet'!G24/'Data Sheet'!G$17 -> 0.036746926 | I13: ='Data Sheet'!H24/'Data Sheet'!H$17 -> 0.035425597 | J13: ='Data Sheet'!I24/'Data Sheet'!I$17 -> 0.034964384 | ... L13: ='Data Sheet'!K24/'Data Sheet'!K$17 -> 0.038194608
B14: ='Data Sheet'!A25 -> Other Income | C14: ='Data Sheet'!B25/'Data Sheet'!B$17 -> 0.028385767 | D14: ='Data Sheet'!C25/'Data Sheet'!C$17 -> 0.035781496 | E14: ='Data Sheet'!D25/'Data Sheet'!D$17 -> 0.029584741 | F14: ='Data Sheet'!E25/'Data Sheet'!E$17 -> 0.029434055 | G14: ='Data Sheet'!F25/'Data Sheet'!F$17 -> 0.029257912 | H14: ='Data Sheet'!G25/'Data Sheet'!G$17 -> 0.011670331 | I14: ='Data Sheet'!H25/'Data Sheet'!H$17 -> 0.020953931 | J14: ='Data Sheet'!I25/'Data Sheet'!I$17 -> 0.015297749 | ... L14: ='Data Sheet'!K25/'Data Sheet'!K$17 -> 0.015517539
B15: ='Data Sheet'!A26 -> Depreciation | C15: ='Data Sheet'!B26/'Data Sheet'!B$17 -> 0.017377538 | D15: ='Data Sheet'!C26/'Data Sheet'!C$17 -> 0.016843836 | E15: ='Data Sheet'!D26/'Data Sheet'!D$17 -> 0.016360151 | F15: ='Data Sheet'!E26/'Data Sheet'!E$17 -> 0.014037675 | G15: ='Data Sheet'!F26/'Data Sheet'!F$17 -> 0.022485011 | H15: ='Data Sheet'!G26/'Data Sheet'!G$17 -> 0.024759863 | I15: ='Data Sheet'!H26/'Data Sheet'!H$17 -> 0.024009929 | J15: ='Data Sheet'!I26/'Data Sheet'!I$17 -> 0.022274659 | ... L15: ='Data Sheet'!K26/'Data Sheet'!K$17 -> 0.020530777
